
from odoo import models, fields, api
from odoo.exceptions import UserError



class SaleOrderInh(models.Model):
    _inherit = 'sale.order'

    partner_balance = fields.Float('Balance', compute='compute_balance', default=0)
    warehouse_ids = fields.Many2many('stock.warehouse', compute='compute_warehouse')
    quo_date = fields.Date('Old Date', default=fields.Date.today)

    @api.depends('warehouse_id')
    def compute_warehouse(self):
        rec = self.env['stock.warehouse'].search([('is_active', '=', True)])
        self.warehouse_ids = rec.ids

    @api.depends('partner_id')
    def compute_balance(self):
        partner_ledger = self.env['account.move.line'].search(
            [('partner_id', '=', self.partner_id.id),
             ('move_id.state', '=', 'posted'), ('full_reconcile_id', '=', False), ('balance', '!=', 0),
             ('account_id.reconcile', '=', True), ('full_reconcile_id', '=', False), '|',
             ('account_id.internal_type', '=', 'payable'), ('account_id.internal_type', '=', 'receivable')])
        bal = 0
        for par_rec in partner_ledger:
            bal = bal + (par_rec.debit - par_rec.credit)
        self.partner_balance = bal

    def action_cancel(self):
        for rec in self.picking_ids:
            if rec.state == 'in_transit' or rec.state == 'done':
                raise UserError('You cannot cancel Sale Order when Delivery is in Transit/Done State.')
        return super(SaleOrderInh, self).action_cancel()




